<mujoco model="pr2_model">
    <worldbody name="base">
        <body name="pr2" pos="0 0 0.5">
            <joint axis="1 0 0" name="robot_x" type="slide" pos="0 0 0" />
            <joint axis="0 1 0" name="robot_y" type="slide" pos="0 0 0" />
            <site name="body_1" pos="0.3 0 0" zaxis="1 0 0" />
            <site name="body_2" pos="0.276 0.195 -0.3" zaxis="0.924 0.0585 0" />
            <site name="body_3" pos="0.212 0.212 -0.3" zaxis="0.707 0.707 0" />
            <site name="body_4" pos="0.195 0.276 -0.3" zaxis="0.0585 0.924 0" />

            <site name="body_5" pos="0 0.3 -0.3" zaxis="0 1 0"/>
            <site name="body_6" pos="-0.195 0.276 -0.30" zaxis="-0.0585 0.924 0"/>
            <site name="body_7" pos="-0.212 0.212 -0.30" zaxis="-0.707 0.707 0"/>
            <site name="body_8" pos="-0.276 0.195 -0.30" zaxis="-0.924 0.0585 0"/>

            <site name="body_9" pos="-0.3 0 -0.3" zaxis="-1 0 0"/>
            <site name="body_10" pos="-0.276 -0.195 -0.30" zaxis="-0.924 -0.0585 0"/>
            <site name="body_11" pos="-0.212 -0.212 -0.30" zaxis="-0.707 -0.707 0"/>
            <site name="body_12" pos="-0.195 -0.276 -0.30" zaxis="-0.0585 -0.924 0"/>

            <site name="body_13" pos="0 -0.3 -0.3" zaxis="0 -1 0"/>
            <site name="body_14" pos="0.195 -0.276 -0.3" zaxis="0.0585 -0.924 0"/>
            <site name="body_15" pos="0.212 -0.212 -0.3" zaxis="0.707 -0.707 0"/>
            <site name="body_16" pos="0.276 -0.195 -0.3" zaxis="0.924 -0.0585 0"/>

            <site name="body_17" pos="0 1.1 -0.3" zaxis="0 1 0"/>

            <geom name="pr2" type="cylinder" size="0.295 0.45" mass="5" rgba="0 0 0 1"/>
            <joint axis="0 0 1" name="robot_theta" type="hinge" pos="0 0 0" limited="false"/>
            <body name="right_finger" pos="-0.35 0.65 0" euler="0 0 -0.05">
                <site name="rf_1" pos="0. 0.35 -0.3" zaxis="0 1 0"/>
                <site name="rf_2" pos="-0.05 0.35 -0.3" zaxis="-1 1 0"/>
                <site name="rf_3" pos="-0.055 0.15 -0.3" zaxis="-1 0 0"/>
                <site name="rf_4" pos="-0.055 -0.15 -0.3" zaxis="-1 0 0"/>
                <site name="rf_5" pos="0.05 0.35 -0.3" zaxis="1 1 0"/>
                <site name="rf_6" pos="-0.055 0 -0.3" zaxis="-1 0 0"/>
                <site name="rf_7" pos="0 0.35 -0.3" zaxis="1 2 0"/>
                <site name="rf_8" pos="-0.055 0.1 -0.3" zaxis="-1 0.5 0"/>
                <site name="rf_9" pos="-0.05 0.3 -0.3" zaxis="-1 0.5 0"/>
                <site name="rf_10" pos="-0.055 -0.3 -0.3" zaxis="-1 0 0"/>
                <site name="rf_11" pos="-0.055  0.3 -0.3" zaxis="-1 0 0"/>
                <site name="rf_12" pos="-0.055 -0.1 -0.3" zaxis="-1 2 0"/>
                <site name="rf_13" pos="-0.055 0.2 -0.3" zaxis="-1 2 0"/>
                <site name="rf_14" pos="-0.055 0.35 -0.3" zaxis="-3 1 0"/>
                <site name="rf_15" pos="-0.055 0.35 -0.3" zaxis="-1 3 0"/>
                <site name="rf_16" pos="-0.055 0.25 -0.3" zaxis="-2 1 0"/>
                <site name="rf_17" pos="-0.055 0.2 -0.3" zaxis="-2 1 0"/>
                <site name="rf_18" pos="-0.055 0.15 -0.3" zaxis="-2 1 0"/>
                <site name="rf_19" pos="-0.055 -0.05 -0.3" zaxis="-2 1 0"/>
                <site name="rf_20" pos="-0.055 -0.15 -0.3" zaxis="-2 1 0"/>
                <site name="rf_21" pos="-0.055 0.15 -0.3" zaxis="-1 1 0"/>
                <site name="rf_22" pos="-0.055 0.35 -0.3" zaxis="-2 1 0"/>
                <site name="rf_23" pos="0. 0.35 -0.3" zaxis="1 2 0"/>
                <site name="rf_24" pos="0. 0.35 -0.3" zaxis="-1 2 0"/>
                <site name="rf_25" pos="0. 0.35 -0.3" zaxis="2 1 0"/>
                <site name="rf_26" pos="0. 0.35 -0.3" zaxis="-2 1 0"/>
                <joint name="right_finger_joint" axis="1 0 0" limited="true" range="-0.1 0.1" type="slide" solreflimit="0.02 0.25" solimplimit="0.99 1. 0.0001" pos="0 0 0" margin="0.02" />
                <geom pos="0 0 0" size="0.05 0.345 0.45" type="box" mass="1" friction="1.9 0.95 0.0005" rgba="0 0 0 1"/>
            </body>
            <body name="left_finger" pos="0.35 0.65 0" euler="0 0 0.05">
                <site name="lf_1" pos="0. 0.35 -0.3" zaxis="0 1 0"/>
                <site name="lf_2" pos="0.05 0.35 -0.3" zaxis="1 1 0"/>
                <site name="lf_3" pos="0.055 0.15 -0.3" zaxis="1 0 0"/>
                <site name="lf_4" pos="0.055 -0.15 -0.3" zaxis="1 0 0"/>
                <site name="lf_5" pos="-0.05 0.35 -0.3" zaxis="-1 1 0"/>
                <site name="lf_6" pos="0.055 0 -0.3" zaxis="1 0 0"/>
                <site name="lf_7" pos="0. 0.35 -0.3" zaxis="-1 2 0"/>
                <site name="lf_8" pos="0.055 0.1 -0.3" zaxis="1 0.5 0"/>
                <site name="lf_9" pos="0.05 0.3 -0.3" zaxis="1 0.5 0"/>
                <site name="lf_10" pos="0.055 -0.3 -0.3" zaxis="1 0 0"/>
                <site name="lf_11" pos="0.055  0.3 -0.3" zaxis="1 0 0"/>
                <site name="lf_12" pos="0.055 -0.1 -0.3" zaxis="1 2 0"/>
                <site name="lf_13" pos="0.055 0.3 -0.3" zaxis="1 2 0"/>
                <site name="lf_14" pos="0.055 0.35 -0.3" zaxis="3 1 0"/>
                <site name="lf_15" pos="0.055 0.35 -0.3" zaxis="1 3 0"/>
                <site name="lf_16" pos="0.055 0.25 -0.3" zaxis="2 1 0"/>
                <site name="lf_17" pos="0.055 0.2 -0.3" zaxis="2 1 0"/>
                <site name="lf_18" pos="0.055 0.15 -0.3" zaxis="2 1 0"/>
                <site name="lf_19" pos="0.055 -0.05 -0.3" zaxis="2 1 0"/>
                <site name="lf_20" pos="0.055 -0.15 -0.3" zaxis="2 1 0"/>
                <site name="lf_21" pos="0.055 0.15 -0.3" zaxis="1 1 0"/>
                <site name="lf_22" pos="0.055 0.35 -0.3" zaxis="2 1 0"/>
                <site name="lf_23" pos="0. 0.35 -0.3" zaxis="-1 2 0"/>
                <site name="lf_24" pos="0. 0.35 -0.3" zaxis="1 2 0"/>
                <site name="lf_25" pos="0. 0.35 -0.3" zaxis="-2 1 0"/>
                <site name="lf_26" pos="0. 0.35 -0.3" zaxis="2 1 0"/>
                <joint name="left_finger_joint" axis="-1 0 0" limited="true" range="-0.1 0.1" type="slide" solreflimit="0.02 0.25" solimplimit="0.99 1. 0.0001" pos="0 0 0" margin="0.02" />
                <geom pos="0 0 0" size="0.05 0.345 0.45" type="box" mass="1" friction="1.9 0.95 0.0005" rgba="0 0 0 1"/>
            </body>
        </body>
    </worldbody>

    <actuator>
        <velocity kv="500" joint="robot_x" name="robot_x" ctrllimited="true" ctrlrange="-20 20" />
        <velocity kv="500" joint="robot_y" name="robot_y" ctrllimited="true" ctrlrange="-20 20" />
        <velocity kv="100" joint="robot_theta" name="robot_theta" ctrllimited="true" ctrlrange="-20 20" />
        <motor gear="50" joint="left_finger_joint" name="left_grip" ctrllimited="true" ctrlrange="-50 500" />
        <motor gear="50" joint="right_finger_joint" name="right_grip" ctrllimited="true" ctrlrange="-50 500" />
    </actuator>

    <sensor>
        <rangefinder name="lidar_1" site="body_1" cutoff="2.5" />
        <rangefinder name="lidar_2" site="body_2" cutoff="2.5" />
        <rangefinder name="lidar_3" site="body_3" cutoff="2.5" />
        <rangefinder name="lidar_4" site="body_4" cutoff="4.5" />
        <rangefinder name="lidar_5" site="body_5" cutoff="2.5" />
        <rangefinder name="lidar_6" site="body_6" cutoff="2.6" />
        <rangefinder name="lidar_7" site="body_7" cutoff="2.5" />
        <rangefinder name="lidar_8" site="body_8" cutoff="2.5" />
        <rangefinder name="lidar_9" site="body_9" cutoff="2.5" />
        <rangefinder name="lidar_10" site="body_10" cutoff="2.5" />
        <rangefinder name="lidar_11" site="body_11" cutoff="2.5" />
        <rangefinder name="lidar_12" site="body_12" cutoff="2.5" />
        <rangefinder name="lidar_13" site="body_13" cutoff="2.5" />
        <rangefinder name="lidar_14" site="body_14" cutoff="2.5" />
        <rangefinder name="lidar_15" site="body_15" cutoff="2.5" />
        <rangefinder name="lidar_16" site="body_16" cutoff="2.5" />

        <rangefinder name="llidar_1" site="lf_1" cutoff="2.5" />
        <rangefinder name="llidar_2" site="lf_2" cutoff="2.5" />
        <rangefinder name="llidar_3" site="lf_3" cutoff="2.5" />
        <rangefinder name="llidar_4" site="lf_4" cutoff="2.5" />
        <rangefinder name="llidar_5" site="lf_5" cutoff="2.5" />
        <rangefinder name="llidar_6" site="lf_6" cutoff="2.5" />
        <rangefinder name="llidar_7" site="lf_7" cutoff="2.5" />
        <rangefinder name="llidar_8" site="lf_8" cutoff="2.5" />
        <rangefinder name="llidar_9" site="lf_9" cutoff="2.5" />
        <rangefinder name="llidar_10" site="lf_10" cutoff="2.5" />
        <rangefinder name="llidar_11" site="lf_11" cutoff="2.5" />
        <rangefinder name="llidar_12" site="lf_12" cutoff="2.5" />
        <rangefinder name="llidar_13" site="lf_13" cutoff="2.5" />
        <rangefinder name="llidar_14" site="lf_14" cutoff="2.5" />
        <rangefinder name="llidar_15" site="lf_15" cutoff="2.5" />
        <rangefinder name="llidar_16" site="lf_16" cutoff="2.5" />
        <rangefinder name="llidar_17" site="lf_17" cutoff="2.5" />
        <rangefinder name="llidar_18" site="lf_18" cutoff="2.5" />
        <rangefinder name="llidar_19" site="lf_19" cutoff="2.5" />
        <rangefinder name="llidar_20" site="lf_20" cutoff="2.5" />
        <rangefinder name="llidar_21" site="lf_21" cutoff="2.5" />
        <rangefinder name="llidar_22" site="lf_22" cutoff="2.5" />
        <rangefinder name="llidar_23" site="lf_23" cutoff="2.5" />
        <rangefinder name="llidar_24" site="lf_24" cutoff="2.5" />
        <rangefinder name="llidar_25" site="lf_25" cutoff="2.5" />
        <rangefinder name="llidar_26" site="lf_26" cutoff="2.5" />

        <rangefinder name="rlidar_1" site="rf_1" cutoff="2.5" />
        <rangefinder name="rlidar_2" site="rf_2" cutoff="2.5" />
        <rangefinder name="rlidar_3" site="rf_3" cutoff="2.5" />
        <rangefinder name="rlidar_4" site="rf_4" cutoff="2.5" />
        <rangefinder name="rlidar_5" site="rf_5" cutoff="2.5" />
        <rangefinder name="rlidar_6" site="rf_6" cutoff="2.5" />
        <rangefinder name="rlidar_7" site="rf_7" cutoff="2.5" />
        <rangefinder name="rlidar_8" site="rf_8" cutoff="2.5" />
        <rangefinder name="rlidar_9" site="rf_9" cutoff="2.5" />
        <rangefinder name="rlidar_10" site="rf_10" cutoff="2.5" />
        <rangefinder name="rlidar_11" site="rf_11" cutoff="2.5" />
        <rangefinder name="rlidar_12" site="rf_12" cutoff="2.5" />
        <rangefinder name="rlidar_13" site="rf_13" cutoff="2.5" />
        <rangefinder name="rlidar_14" site="rf_14" cutoff="2.5" />
        <rangefinder name="rlidar_15" site="rf_15" cutoff="2.5" />
        <rangefinder name="rlidar_16" site="rf_16" cutoff="2.5" />
        <rangefinder name="rlidar_17" site="rf_17" cutoff="2.5" />
        <rangefinder name="rlidar_18" site="rf_18" cutoff="2.5" />
        <rangefinder name="rlidar_19" site="rf_19" cutoff="2.5" />
        <rangefinder name="rlidar_20" site="rf_20" cutoff="2.5" />
        <rangefinder name="rlidar_21" site="rf_21" cutoff="2.5" />
        <rangefinder name="rlidar_22" site="rf_22" cutoff="2.5" />
        <rangefinder name="rlidar_23" site="rf_23" cutoff="2.5" />
        <rangefinder name="rlidar_24" site="rf_24" cutoff="2.5" />
        <rangefinder name="rlidar_25" site="rf_25" cutoff="2.5" />
        <rangefinder name="rlidar_26" site="rf_26" cutoff="2.5" />

        <rangefinder name="far_forward" site="body_17" cutoff="2.5" />
    </sensor>
</mujoco>
