<mujoco model="pr2_model">
    <worldbody name="base">
        <body name="pr2" pos="0 0 0.5">
            <joint axis="1 0 0" name="robot_x" type="slide" pos="0 0 0" armature="0.02"/>
            <joint axis="0 1 0" name="robot_y" type="slide" pos="0 0 0" armature="0.02"/>
            <joint axis="0 0 1" name="robot_theta" type="hinge" pos="0 0 0" armature="0.01" limited="true" range="-3.15 3.15"/>
            <geom name="pr2" type="cylinder" size="0.295 0.45" mass="5"/>
            <site name="body_1" pos="0 -0.3 0" zaxis="-1 0 0" />
            <site name="body_2" pos="0.3 0 0" zaxis="0 1 0" />
            <site name="body_3" pos="-0.3 0 0" zaxis="0 -1 0" />
            <site name="body_4" pos="0 -0.3 0" zaxis="-1 0 0" />
            <site name="body_5" pos="0.707 -0.707 0" zaxis="1 -1 0"/>
            <site name="body_6" pos="-0.707 -0.707 0" zaxis="-1 -1 0"/>
            <site name="body_7" pos="0 1.0 0" zaxis="0 1 0"/>
            <body name="right_finger" pos="-0.35 0.65 0" euler="0 0 -0.05">
                <site name="rf_1" pos="-0.4 0.3 0" zaxis="-1 0 0"/>
                <site name="rf_2" pos="-0.4 0 0" zaxis="-1 0 0"/>
                <site name="rf_3" pos="-0.4 -0.3 0" zaxis="-1 -0 0"/>
                <site name="rf_4" pos="-0.35 0.35 0" zaxis="0 1 0"/>
                <site name="rf_5" pos="-0.4 0.35 0" zaxis="-1 1 0"/>
                <joint name="right_finger_joint" axis="1 0 0" limited="true" range="-0.1 0.1" type="slide" solreflimit="0.02 0.95" solimplimit="0.99 1. 0.0001" armature="0." pos="0 0 0" />
                <geom pos="0 0 0" size="0.05 0.345 0.45" type="box" mass="0.5" friction="1.9 0.95 0.0005" />
            </body>
            <body name="left_finger" pos="0.35 0.65 0" euler="0 0 0.05">
                <site name="lf_1" pos="0.4 0.3 0" zaxis="1 0 0"/>
                <site name="lf_2" pos="0.4 0 0" zaxis="1 0 0"/>
                <site name="lf_3" pos="0.4 -0.3 0" zaxis="1 0 0"/>
                <site name="lf_4" pos="0.35 0.35 0" zaxis="0 1 0"/>
                <site name="lf_5" pos="0.4 0.35 0" zaxis="1 1 0"/>
                <joint name="left_finger_joint" axis="-1 0 0" limited="true" range="-0.1 0.1" type="slide" solreflimit="0.02 0.95" solimplimit="0.99 1. 0.0001" armature="0." pos="0 0 0" />
                <geom pos="0 0 0" size="0.05 0.345 0.45" type="box" mass="0.5" friction="1.9 0.95 0.0005" />
            </body>
        </body>
    </worldbody>

    <actuator>
        <velocity kv="500" joint="robot_x" name="robot_x" ctrllimited="true" ctrlrange="-20 20" />
        <velocity kv="500" joint="robot_y" name="robot_y" ctrllimited="true" ctrlrange="-20 20" />
        <velocity kv="100" joint="robot_theta" name="robot_theta" ctrllimited="true" ctrlrange="-20 20" />
        <motor gear="25" joint="left_finger_joint" name="left_grip" ctrllimited="true" ctrlrange="-5000 5000" />
        <motor gear="25" joint="right_finger_joint" name="right_grip" ctrllimited="true" ctrlrange="-5000 5000" />
    </actuator>
</mujoco>
